Workbook

Sheet 사용법
B2: 리커버핏 Coach 검수표
B3: 생성일 2026-09-02
B5: ■ 이 파일은 무엇인가요
B6: 앱이 사용자에게 내보내는 안전 기준과 운동·영양 내용을 전문가가 확인하기 위한 표입니다.
B7: 아래 기준들은 아직 임상 근거로 검증된 값이 아닙니다. 기획 단계에서 정한 값입니다.
B9: ■ 어떻게 표시하나요
B10: 노란색 칸에만 적으시면 됩니다. 나머지 칸은 그대로 두세요.
B11: '판정' 칸을 누르면 O / △ / X 를 고를 수 있습니다. 직접 입력하셔도 됩니다.
B13: O → 이대로 괜찮음
B14: △ → 수정 필요 (오른쪽 '의견' 칸에 수정안을 적어 주세요)
B15: X → 빼야 함 / 위험함
B17: ■ 시트 안내
... B26: 이 파일을 그대로 저장해서 보내 주시면 됩니다.

Sheet 영상후보
A1: 운동 id | B1: 운동명 | C1: 부위 / 단계 | D1: 후보 영상 링크 | E1: 채널 · 비고 | F1: 판정 | G1: 의견
A2: knee-p1-01 | B2: 쿼드셋 | C2: 무릎 P1 | D2: https://www.youtube.com/watch?v=d5A5LWDOPE0 | E2: Quad Set | Knee Stability Series · 영어
A3: knee-p1-01 | B3: 쿼드셋 | C3: 무릎 P1 | D3: https://www.youtube.com/watch?v=5TUK4uT2nnw | E3: Physical Therapy Exercises · 영어 · 물리치료사
A4: knee-p1-01 | B4: 쿼드셋 | C4: 무릎 P1 | D4: https://www.youtube.com/watch?v=au62CidApd0 | E4: Ask Doctor Jo · 영어 · 물리치료사
A5: knee-p1-01 | B5: 쿼드셋 | C5: 무릎 P1 | D5: https://www.youtube.com/watch?v=mzTKLYET6QA | E5: MedBridge · 영어 · 교육기관
A6: knee-p1-02 | B6: 힐슬라이드 | C6: 무릎 P1 | D6: https://www.youtube.com/watch?v=t4HVx5NDeHc | E6: 통증 없이 무릎 굽히는 힐 슬라이드 · 한국어
A7: knee-p1-02 | B7: 힐슬라이드 | C7: 무릎 P1 | D7: https://www.youtube.com/watch?v=m06ilKpj87g | E7: 무릎 전문의 재활운동 · 한국어 · 의사
A8: knee-p1-02 | B8: 힐슬라이드 | C8: 무릎 P1 | D8: https://www.youtube.com/watch?v=W3_BUipgYU4 | E8: Seated Active Heel Slide · 영어
A9: knee-p1-03 | B9: 누워서 다리 들기 (SLR) | C9: 무릎 P1 | D9: https://www.youtube.com/watch?v=WqI8ln0MpjQ | E9: [무릎 재활 1주차] · 한국어 · 단계별 시리즈
A10: knee-p1-03 | B10: 누워서 다리 들기 (SLR) | C10: 무릎 P1 | D10: https://www.youtube.com/watch?v=iwiVVQ22vqw | E10: 누워서 쉽게 따라 할 수 있는 무릎 운동 · 한국어
A11: knee-p1-03 | B11: 누워서 다리 들기 (SLR) | C11: 무릎 P1 | D11: https://www.youtube.com/watch?v=tNLINRNEQtM | E11: 무릎 통증을 줄여주는 무릎 운동 · 한국어
A12: back-p1-02 | B12: 골반 틸트 | C12: 허리 P1 | D12: https://www.youtube.com/watch?v=SaUhRNOjwUg | E12: 골반 후경사 운동(누운자세) · 한국어 · 앱 자세와 가장 가까움
A13: back-p1-02 | B13: 골반 틸트 | C13: 허리 P1 | D13: https://www.youtube.com/watch?v=HAdd1sP6ruE | E13: 누워서 골반 움직이기 · 한국어
... A29: neck-p1-01 | B29: 턱 당기기 (누워서) | C29: 목 P1 | D29: https://www.youtube.com/watch?v=H0r_ntsH4v4 | E29: ⚠ 거북목 교정 턱 당기기 제대로 하는법 · 한국어
A31: ⚠ 자세가 정확한지·안전한지 확인하지 않은 후보입니다. 조회수와 댓글 수는 확인하지 못했습니다. ⚠ 표시된 '턱 당기기'는 모두에게 맞는 운동이 아니라는 견해가 있어 특히 주의가 필요합니다.

Sheet 위험신호
A1: # | B1: 문항 | C1: 보조 설명 | D1: 판정 | E1: 수정 의견
A2: 1 | B2: 심한 외상 후 통증이 있다 | C2: 크게 부딪히거나 넘어진 뒤 생긴 통증
A3: 2 | B3: 골절이나 탈구가 의심된다 | C3: 뚝 소리가 났거나, 관절이 빠진 느낌이 있었다
A4: 3 | B4: 관절 모양이 이상하다 | C4: 평소와 다르게 튀어나오거나 휘었다
A5: 4 | B5: 체중을 싣기 어렵다 | C5: 아픈 다리로 서 있거나 걷기가 거의 안 된다
A6: 5 | B6: 심한 붓기나 열감이 있다 | C6: 눈에 띄게 붓고 만지면 뜨겁다
A7: 6 | B7: 저림, 마비, 감각 이상이 있다 | C7: 찌릿하거나 감각이 둔한 부위가 있다
A8: 7 | B8: 힘이 빠지는 증상이 있다 | C8: 물건을 놓치거나 다리에 힘이 안 들어간다
A9: 8 | B9: 허리 통증과 함께 대소변에 이상이 있다 | C9: 소변이 잘 안 나오거나 조절이 어렵다
A10: 9 | B10: 가슴 통증, 호흡곤란, 실신할 것 같은 느낌이 있었다 | C10: 운동 중 또는 평상시 모두 포함
A11: 10 | B11: 원인 모를 체중 감소가 있다 | C11: 다이어트를 하지 않았는데 체중이 줄었다
A12: 11 | B12: 밤에 가만히 있어도 심하게 아프다 | C12: 자다가 통증으로 깬다
A13: 12 | B13: 수술 직후이거나 의사에게 운동 제한을 안내받았다 | C13: 의료진 지시가 항상 우선입니다
A15: 규칙: 위 12개 중 하나라도 해당하면 운동 루틴을 제공하지 않고 전문가 상담 안내로 보냅니다. 점수화하지 않고, 대체 운동도 주지 않습니다.
A16: 여쭙고 싶은 것: 빠진 항목이 있습니까? 빼도 되는 항목이 있습니까? 문구가 일반인에게 오해 없이 전달됩니까?
A17: 추가로 넣어야 할 항목이 있다면 여기에 적어 주세요 →

Sheet 운동목록
A1: 운동 id | B1: 운동명 | C1: 분류 | D1: 단계 | E1: 난이도 | F1: 목적 | G1: 방법 | H1: 주의사항 | I1: 판정 | J1: 의견
A2: ankle-p1-01 | B2: 발목 알파벳 | C2: 발목 회복운동 | D2: P1 | E2: 초급 | F2: 발목을 여러 방향으로 부드럽게 움직여 굳는 것을 막습니다. | G2: 앉거나 누워서 다리를 폅니다. → 발끝으로 공중에 ㄱ부터 ㅎ까지 글자를 씁니다. → 발목만 움직이고 다리는 고정합니다.
A3: ankle-p1-02 | B3: 발목 펌프 | C3: 발목 회복운동 | D3: P1 | E3: 초급 | F3: 발목을 위아래로 움직여 부기를 줄이고 순환을 돕습니다. | G3: 다리를 펴고 앉거나 눕습니다. → 발끝을 몸 쪽으로 당겼다가 반대로 밉니다. → 20회 반복합니다.
A4: ankle-p1-03 | B4: 종아리 스트레칭 (수건) | C4: 발목 회복운동 | D4: P1 | E4: 초급 | F4: 굳은 종아리를 늘려 발목이 움직일 공간을 만듭니다. | G4: 다리를 펴고 앉습니다. → 수건을 발바닥에 걸고 몸 쪽으로 부드럽게 당깁니다. → 20초 유지합니다. | H4: 발바닥이나 종아리에 찌릿한 통증이 있으면 중단하세요.
A5: ankle-p2-01 | B5: 밴드 발목 4방향 | C5: 발목 회복운동 | D5: P2 | E5: 초급 | F5: 발목을 잡아 주는 근육을 네 방향으로 고르게 깨웁니다. | G5: 밴드를 발에 걸고 반대쪽을 고정합니다. → 발끝을 위·아래·안쪽·바깥쪽으로 각각 밀어 냅니다. → 각 방향 12회씩 진행합니다.
A6: ankle-p2-02 | B6: 양발 카프레이즈 | C6: 발목 회복운동 | D6: P2 | E6: 초급 | F6: 종아리 근력을 되찾아 발목을 안정시킵니다. | G6: 벽이나 의자를 잡고 어깨너비로 섭니다. → 뒤꿈치를 천천히 들어 올립니다. → 2초 유지한 뒤 천천히 내립니다.
A7: ankle-p2-03 | B7: 균형 서기 (두 발 → 한 발) | C7: 발목 회복운동 | D7: P2 | E7: 초급 | F7: 발목이 몸의 흔들림을 잡아 주는 감각을 되살립니다. | G7: 벽 옆에 서서 두 발로 균형을 잡습니다. → 익숙해지면 한 발로 20초 서 있습니다. → 반대쪽도 진행합니다. | H7: 휘청거림이 크면 벽 옆에서만 진행하세요.
A8: ankle-p3-01 | B8: 한 발 카프레이즈 | C8: 발목 회복운동 | D8: P3 | E8: 중급 | F8: 한 발로 체중을 들어 올리는 종아리 근력을 회복합니다. | G8: 벽을 손끝으로 짚고 한 발로 섭니다. → 뒤꿈치를 천천히 들어 올립니다. → 2초 유지 후 천천히 내립니다.
A9: ankle-p3-02 | B9: 싱글레그 밸런스 + 리치 | C9: 발목 회복운동 | D9: P3 | E9: 중급 | F9: 한 발로 버티며 균형을 잡는 능력을 끌어올립니다. | G9: 한 발로 섭니다. → 반대쪽 발끝으로 앞·옆·뒤 바닥을 가볍게 터치합니다. → 각 방향 8회씩 진행합니다.
A10: ankle-p3-03 | B10: 미니 스쿼트 (한 발 지지) | C10: 발목 회복운동 | D10: P3 | E10: 중급 | F10: 체중을 실은 상태에서 발목이 버티는 힘을 기릅니다. | G10: 한 발로 서서 벽을 손끝으로 짚습니다. → 무릎을 살짝 굽혀 얕게 앉았다 일어납니다. → 10회 반복합니다.
A11: ankle-p4-01 | B11: 홉 준비 (제자리 작은 점프) | C11: 발목 회복운동 | D11: P4 | E11: 중급 | F11: 가볍게 뛰고 착지하는 동작에 발목을 다시 적응시킵니다. | G11: 두 발로 제자리에서 아주 낮게 뜁니다. → 발 앞쪽으로 부드럽게 착지합니다. → 10회 반복합니다. | H11: 착지할 때 통증이나 불안정한 느낌이 있으면 중단하세요.
A12: ankle-p4-02 | B12: 사이드 스텝 | C12: 발목 회복운동 | D12: P4 | E12: 중급 | F12: 옆으로 움직이는 상황에서 발목을 안정시킵니다. | G12: 무릎을 살짝 굽힌 자세로 섭니다. → 옆으로 10걸음 이동한 뒤 반대로 돌아옵니다.
A13: ankle-p4-03 | B13: 민첩성 사다리 (라인 스텝) | C13: 발목 회복운동 | D13: P4 | E13: 중급 | F13: 빠른 발놀림에 발목을 다시 적응시킵니다. | G13: 바닥에 선을 하나 정합니다. → 선을 앞뒤로 넘나들며 가볍게 스텝을 밟습니다. → 20초 진행합니다. | H13: 통증이 생기면 즉시 중단하세요.
A14: back-p1-01 | B14: 복식호흡 (누워서) | C14: 허리 회복운동 | D14: P1 | E14: 초급 | F14: 허리 주변 긴장을 낮추고 배 속 근육을 준비합니다. | G14: 무릎을 세우고 눕습니다. → 한 손은 가슴, 한 손은 배에 둡니다. → 코로 마시며 배를 부풀리고, 입으로 길게 내쉽니다. → 1분간 이어갑니다.
A15: back-p1-02 | B15: 골반 틸트 | C15: 허리 회복운동 | D15: P1 | E15: 초급 | F15: 허리를 아주 작은 범위로 움직여 뻣뻣함을 풉니다. | G15: 무릎을 세우고 눕습니다. → 허리와 바닥 사이 틈을 없애듯 골반을 말아 넣습니다. → 3초 유지한 뒤 천천히 풉니다. | H15: 통증이 늘면 범위를 더 줄이세요.
A16: back-p1-03 | B16: 무릎 당기기 | C16: 허리 회복운동 | D16: P1 | E16: 초급 | F16: 허리 뒤쪽을 부드럽게 늘려 뻣뻣함을 줄입니다. | G16: 천장을 보고 눕습니다. → 한쪽 무릎을 두 손으로 잡아 가슴 쪽으로 당깁니다. → 20초 유지한 뒤 바꿉니다.
A17: back-p2-01 | B17: 데드버그 | C17: 허리 회복운동 | D17: P2 | E17: 초급 | F17: 허리를 고정한 채 팔다리를 움직이는 안정성을 기릅니다. | G17: 누워서 무릎과 고관절을 90도로 듭니다. → 양팔을 천장으로 뻗습니다. → 숨을 내쉬며 한쪽 팔과 반대쪽 다리를 뻗습니다. → 허리가 뜨지 않는 범위까지만 진행합니다. | H17: 허리 통증이 생기면 팔만 또는 다리만 진행하세요.
A18: back-p2-02 | B18: 버드독 | C18: 허리 회복운동 | D18: P2 | E18: 초급 | F18: 허리를 흔들지 않고 팔다리를 뻗는 힘을 기릅니다. | G18: 네 발로 엎드립니다. → 한쪽 팔과 반대쪽 다리를 바닥과 나란히 뻗습니다. → 3초 유지한 뒤 천천히 내립니다.
A19: back-p2-03 | B19: 사이드 플랭크 (무릎 대고) | C19: 허리 회복운동 | D19: P2 | E19: 초급 | F19: 허리 옆쪽을 잡아 주는 근육을 깨웁니다. | G19: 옆으로 누워 팔꿈치를 어깨 아래에 둡니다. → 무릎을 굽힌 채 골반을 들어 올립니다. → 어깨-골반-무릎이 한 줄이 되게 20초 버팁니다. | H19: 어깨에 통증이 있으면 중단하세요.
A20: back-p3-01 | B20: 힙힌지 | C20: 허리 회복운동 | D20: P3 | E20: 중급 | F20: 허리 대신 고관절로 숙이는 힘을 되찾습니다. | G20: 어깨너비로 서서 무릎을 살짝 굽힙니다. → 엉덩이를 뒤로 밀며 상체를 숙입니다. → 햄스트링이 당기는 지점에서 멈추고 돌아옵니다.
A21: back-p3-02 | B21: 박스 스쿼트 | C21: 허리 회복운동 | D21: P3 | E21: 중급 | F21: 허리에 부담이 적은 형태로 앉고 서는 힘을 회복합니다. | G21: 의자를 뒤에 두고 어깨너비로 섭니다. → 엉덩이를 뒤로 빼며 천천히 앉습니다. → 의자에 닿으면 바로 일어납니다.
A22: back-p3-03 | B22: 팔로프 프레스 | C22: 허리 회복운동 | D22: P3 | E22: 중급 | F22: 몸통이 돌아가지 않게 버티는 힘을 기릅니다. | G22: 밴드를 옆쪽에 고정하고 가슴 앞에 양손으로 잡습니다. → 몸통이 돌아가지 않게 버티며 팔을 앞으로 뻗습니다. → 천천히 가슴으로 돌아옵니다.
A23: back-p4-01 | B23: 파머스 캐리 | C23: 허리 회복운동 | D23: P4 | E23: 중급 | F23: 물건을 들고 걷는 일상 동작에 다시 익숙해집니다. | G23: 양손에 덤벨을 들고 바르게 섭니다. → 어깨를 편 채 30초 동안 천천히 걷습니다. | H23: 허리에 통증이 오면 즉시 내려놓으세요.
A24: back-p4-02 | B24: 리버스 런지 | C24: 허리 회복운동 | D24: P4 | E24: 중급 | F24: 한 다리로 버티며 허리를 안정시키는 능력을 회복합니다. | G24: 바르게 섭니다. → 한 발을 뒤로 크게 내딛으며 앞무릎을 굽힙니다. → 앞발로 바닥을 밀며 돌아옵니다.
A25: back-p4-03 | B25: 루마니안 데드리프트 (가벼운 무게) | C25: 허리 회복운동 | D25: P4 | E25: 중급 | F25: 숙였다 일어나는 동작의 힘을 실제 무게로 회복합니다. | G25: 가벼운 덤벨을 허벅지 앞에 들고 섭니다. → 무릎을 살짝 굽힌 채 엉덩이를 뒤로 밀며 내립니다. → 햄스트링이 당기는 지점에서 엉덩이 힘으로 일어납니다. | H25: 허리에 통증이 생기면 무게를 빼고 힙힌지로 돌아가세요.
A26: warmup-01 | B26: 목·어깨 돌리기 | C26: 동적웜업 | D26: - | E26: 초급 | F26: 상체를 부드럽게 깨워 본운동을 준비합니다. | G26: 어깨너비로 섭니다. → 어깨를 뒤로 크게 10회 돌립니다. → 고개를 좌우로 천천히 각 5회 돌립니다. | H26: 어지럽거나 팔이 저리면 목 동작을 빼고 진행하세요.
A27: warmup-02 | B27: 캣카우 | C27: 동적웜업 | D27: - | E27: 초급 | F27: 척추를 마디마디 움직여 허리와 등을 준비합니다. | G27: 네 발로 엎드립니다. 손은 어깨 아래, 무릎은 골반 아래에 둡니다. → 숨을 내쉬며 등을 둥글게 말아 올립니다. → 숨을 마시며 가슴을 열고 등을 부드럽게 내립니다. | H27: 손목이 아프면 주먹을 쥐거나 매트를 접어 받치세요.
A28: warmup-03 | B28: 월드 그레이티스트 스트레치 | C28: 동적웜업 | D28: - | E28: 중급 | F28: 고관절과 등을 한 번에 열어 주는 종합 웜업 동작입니다. | G28: 런지 자세로 한 발을 크게 앞으로 내딛습니다. → 양손을 앞발 안쪽 바닥에 놓습니다. → 앞발 쪽 팔을 하늘로 크게 열어 올리며 몸통을 돌립니다. → 시선은 손끝을 따라갑니다. | H28: 무릎이나 허리에 통증이 있으면 범위를 줄이거나 빼세요.
A29: warmup-04 | B29: 레그스윙 | C29: 동적웜업 | D29: - | E29: 초급 | F29: 고관절과 햄스트링의 움직임 범위를 넓힙니다. | G29: 벽이나 기둥을 한 손으로 잡습니다. → 한쪽 다리를 앞뒤로 편하게 흔듭니다. → 좌우 방향으로도 같은 횟수만큼 흔듭니다. | H29: 고관절 앞쪽에 찝히는 느낌이 있으면 범위를 줄이세요.
A30: warmup-05 | B30: 인치웜 | C30: 동적웜업 | D30: - | E30: 중급 | F30: 어깨와 코어를 함께 깨우고 뒤쪽 사슬을 늘립니다. | G30: 선 자세에서 상체를 숙여 손을 바닥에 짚습니다. → 손으로 걸어 나가 플랭크 자세를 만듭니다. → 잠시 버틴 뒤 발을 손 쪽으로 걸어 돌아옵니다. | H30: 손목이나 어깨가 아프면 중단하세요.
A31: warmup-06 | B31: 사이드 런지 | C31: 동적웜업 | D31: - | E31: 초급 | F31: 옆으로 움직이는 방향의 고관절과 내전근을 준비합니다. | G31: 다리를 넓게 벌리고 섭니다. → 한쪽으로 체중을 옮기며 그쪽 무릎을 굽힙니다. → 반대쪽 다리는 편 상태를 유지합니다. → 가운데로 돌아와 반대쪽을 진행합니다. | H31: 무릎 안쪽에 통증이 있으면 범위를 줄이세요.
A32: warmup-07 | B32: 스킵 (제자리) | C32: 동적웜업 | D32: - | E32: 초급 | F32: 심박수를 올려 몸을 데웁니다. | G32: 제자리에서 한 발씩 가볍게 뛰며 무릎을 들어 올립니다. → 팔은 자연스럽게 흔듭니다. → 30초 동안 이어갑니다. | H32: 무릎이나 발목에 통증이 있으면 제자리 걷기로 바꾸세요.
A33: warmup-08 | B33: 버트킥 (제자리) | C33: 동적웜업 | D33: - | E33: 초급 | F33: 허벅지 뒤쪽을 깨우고 심박수를 유지합니다. | G33: 제자리에서 가볍게 뛰며 발뒤꿈치를 엉덩이 쪽으로 찹니다. → 상체는 세운 상태를 유지합니다. → 30초 동안 이어갑니다. | H33: 햄스트링에 당기는 통증이 있으면 중단하세요.
A34: func-01 | B34: 박스 스쿼트 | C34: 기능성 운동 | D34: - | E34: 초급 | F34: 의자를 기준으로 안전하게 앉는 깊이를 익힙니다. | G34: 의자를 뒤에 두고 어깨너비로 섭니다. → 엉덩이를 뒤로 빼며 천천히 앉습니다. → 의자에 살짝 닿으면 바로 일어납니다. | H34: 무릎 앞쪽에 통증이 생기면 앉는 깊이를 줄이세요.
A35: func-02 | B35: 고블렛 스쿼트 | C35: 기능성 운동 | D35: - | E35: 중급 | F35: 앞쪽에 무게를 들어 자세를 세운 채 앉는 힘을 기릅니다. | G35: 덤벨을 가슴 앞에 세워 잡습니다. → 어깨너비로 서서 엉덩이를 뒤로 빼며 앉습니다. → 허벅지가 바닥과 가까워지는 지점까지 앉았다 일어납니다. | H35: 허리나 무릎에 통증이 있으면 맨몸 스쿼트로 바꾸세요.
A36: func-03 | B36: 힙힌지 (막대 이용) | C36: 기능성 운동 | D36: - | E36: 초급 | F36: 허리를 굽히지 않고 고관절로 숙이는 법을 익힙니다. | G36: 막대를 등 뒤에 세로로 대고 뒤통수·등·엉덩이 세 곳에 닿게 합니다. → 무릎을 살짝 굽힌 채 엉덩이를 뒤로 밀며 숙입니다. → 세 곳이 떨어지지 않는 범위까지만 숙였다 돌아옵니다. | H36: 허리 통증이나 다리 저림이 있으면 중단하세요.
... A44: knee-p1-01 | B44: 쿼드셋 | C44: 무릎 회복운동 | D44: P1 | E44: 초급 | F44: 무릎을 움직이지 않고 허벅지 앞 근육을 깨웁니다. | G44: 다리를 펴고 앉거나 눕습니다. → 무릎 뒤로 바닥을 누른다는 느낌으로 허벅지 앞에 힘을 줍니다. → 5초 유지한 뒤 천천히 풉니다. | H44: 무릎 안쪽이 찌르듯 아프면 중단하세요.
A45: knee-p1-02 | B45: 힐슬라이드 | C45: 무릎 회복운동 | D45: P1 | E45: 초급 | F45: 무릎을 굽히고 펴는 범위를 아프지 않게 되찾습니다. | G45: 천장을 보고 누워 다리를 폅니다. → 발뒤꿈치를 바닥에 붙인 채 엉덩이 쪽으로 미끄러뜨립니다. → 통증이 없는 지점까지만 굽혔다 천천히 폅니다.
A46: knee-p1-03 | B46: 누워서 다리 들기 (SLR) | C46: 무릎 회복운동 | D46: P1 | E46: 초급 | F46: 무릎을 굽히지 않고 허벅지 앞 근력을 기릅니다. | G46: 한쪽 무릎은 세우고 반대쪽 다리는 폅니다. → 편 다리의 허벅지 앞에 먼저 힘을 줍니다. → 다리를 30cm 정도 들어 올린 뒤 천천히 내립니다. | H46: 허리가 아프면 반대쪽 무릎을 더 세우세요.
A47: knee-p2-01 | B47: 글루트 브릿지 | C47: 무릎 회복운동 | D47: P2 | E47: 초급 | F47: 엉덩이 힘을 키워 무릎이 받는 부담을 나눕니다. | G47: 무릎을 세우고 눕습니다. → 배에 힘을 준 뒤 엉덩이에 힘을 주며 골반을 들어 올립니다. → 허리를 꺾지 않고 천천히 내려옵니다. | H47: 허리로 드는 느낌이 강하면 중단하고 쉬운 동작으로 바꾸세요.
...

Sheet 영양
A1: 트랙 | B1: 대상 | C1: 탄수화물 % | D1: 단백질 % | E1: 지방 % | F1: 핵심 원칙 | G1: 학생 안내 | H1: 판정 | I1: 의견
A2: 건강 체중관리 | B2: 무리하지 않고 식사의 질을 바꾸고 싶은 사용자 | C2: 35~45 | D2: 25~35 | E2: 20~30 | F2: 굶지 않습니다. 끼니를 거르면 다음 끼니에 몰아 먹게 됩니다. / 단백질과 채소를 먼저 채우고 나머지를 채웁니다. / 단 음료를 물이나 우유로 바꿉니다. / 야식 빈도를 조금씩 줄입니다. | G2: 식사를 거르지 않습니다. / 단 음료 대신 물이나 우유를 선택합니다. / 급식에서 단백질 반찬과 채소를 먼저 챙깁니다. / 체중 숫자보다 컨디션과 식사 규칙성을 봅니다.
A3: 벌크업 / 근육량 증가 | B3: 근육량을 늘리고 싶은 사용자 | C3: 45~55 | D3: 20~25 | E3: 20~30 | F3: 총 식사량이 부족하면 근육이 늘지 않습니다. 끼니를 챙기는 것이 먼저입니다. / 매 끼니 단백질을 손바닥 1개분 이상 챙깁니다. / 운동 후 1시간 이내에 탄수화물과 단백질을 함께 먹습니다. / 간식을 한 끼처럼 활용합니다. | G3: 매 끼니 단백질 손바닥 1개분을 챙깁니다. / 운동한 날에는 밥과 단백질을 평소보다 조금 더 챙깁니다. / 보충제보다 실제 음식으로 먼저 채웁니다.
A4: 일반 건강식 | B4: 규칙적이고 균형 잡힌 식사를 하고 싶은 사용자 | C4: 45~55 | D4: 15~25 | E4: 20~30 | F4: 하루 세 끼를 비슷한 시간에 먹습니다. / 한 끼에 단백질·채소·탄수화물 세 가지를 채웁니다. / 물을 충분히 마십니다. / 잠을 충분히 잡니다. 회복은 잘 때 일어납니다. | G4: 아침을 거르지 않습니다. / 급식에서 단백질과 채소를 먼저 챙깁니다. / 물을 자주 마십니다. / 잠을 충분히 잡니다.
A5: 회복 / 면역 / 미네랄 | B5: 부상 회복 중이거나 컨디션을 끌어올리고 싶은 사용자 | C5: 40~50 | D5: 20~30 | E5: 20~30 | F5: 회복에는 단백질이 평소보다 조금 더 필요합니다. / 채소와 과일로 비타민과 미네랄을 채웁니다. / 수분을 충분히 챙깁니다. / 잠이 부족하면 회복이 느려집니다. | G5: 다치거나 아플 때는 오히려 잘 먹어야 회복이 빠릅니다. / 매 끼니 단백질 손바닥 1개분과 채소 주먹 2개분을 챙깁니다. / 물을 자주 마시고 잠을 충분히 잡니다.
A7: 여쭙고 싶은 것: 탄단지 비율이 최신 한국인 영양소 섭취기준과 맞습니까? 성장기 청소년에게 그대로 적용해도 됩니까? 빠진 주의사항이 있습니까?

Sheet 기준값
A1: 구분 | B1: 기준 | C1: 앱의 반응 | D1: 판정 | E1: 의견
A2: 설문 시점 | B2: 통증 7점 이상 | C2: 운동 제공 안 함, 전문가 상담 안내
A3: 설문 시점 | B3: 통증 4~6점 | C3: Phase 1 (통증 완화 / 가동성 회복)
A4: 설문 시점 | B4: 통증 1~3점 | C4: Phase 2 (안정화 / 근육 활성화)
A5: 설문 시점 | B5: 통증 0점 | C5: 회복운동 대상 아님. 목표별 루틴
A6: 운동 중 | B6: 통증 0~3점 | C6: 현재 루틴 유지
A7: 운동 중 | B7: 통증 4~5점 | C7: 횟수 절반, 가동범위 축소, 쉬운 동작으로
A8: 운동 중 | B8: 통증 6점 이상 | C8: 해당 운동 중단, 기록 저장, 상담 안내
A9: 운동 후 | B9: 통증이 운동 전보다 높음 | C9: 다음 루틴 강도 하향
A10: 위험도 | B10: 위험 신호 1개 이상 또는 통증 7점 이상 | C10: Red — 운동 제공 중단
A11: 위험도 | B11: 통증 4~6점 또는 붓기·당일 발생·상시 통증 | C11: Yellow — 저강도 회복운동
A12: 위험도 | B12: 통증 0~3점, 위험 신호 없음 | C12: Green — 회복·교정 운동
A13: 위험도 | B13: 통증 0점 + 주 3회 이상 운동 + 수행능력 목표 | C13: Performance — 기능성 운동
A15: 여쭙고 싶은 것: 차단 기준 7점이 타당합니까? 더 낮춰야 합니까? 3개월 이상 지속되는 통증은 점수와 무관하게 차단해야 합니까? (현재는 점수만 봅니다)

Sheet 진행현황
A1: 시트 | B1: 전체 | C1: O | D1: △ | E1: X | F1: 남음
A2: 영상후보 | B2: 28 | C2: =COUNTIF(영상후보!$F$2:$F$29,"O") | D2: =COUNTIF(영상후보!$F$2:$F$29,"△") | E2: =COUNTIF(영상후보!$F$2:$F$29,"X") | F2: =B2-C2-D2-E2
A3: 위험신호 | B3: 12 | C3: =COUNTIF(위험신호!$D$2:$D$13,"O") | D3: =COUNTIF(위험신호!$D$2:$D$13,"△") | E3: =COUNTIF(위험신호!$D$2:$D$13,"X") | F3: =B3-C3-D3-E3
A4: 운동목록 | B4: 86 | C4: =COUNTIF(운동목록!$I$2:$I$87,"O") | D4: =COUNTIF(운동목록!$I$2:$I$87,"△") | E4: =COUNTIF(운동목록!$I$2:$I$87,"X") | F4: =B4-C4-D4-E4
A5: 영양 | B5: 4 | C5: =COUNTIF(영양!$H$2:$H$5,"O") | D5: =COUNTIF(영양!$H$2:$H$5,"△") | E5: =COUNTIF(영양!$H$2:$H$5,"X") | F5: =B5-C5-D5-E5
A6: 기준값 | B6: 12 | C6: =COUNTIF(기준값!$D$2:$D$13,"O") | D6: =COUNTIF(기준값!$D$2:$D$13,"△") | E6: =COUNTIF(기준값!$D$2:$D$13,"X") | F6: =B6-C6-D6-E6
A7: 합계 | B7: =SUM(B2:B6) | C7: =SUM(C2:C6) | D7: =SUM(D2:D6) | E7: =SUM(E2:E6) | F7: =SUM(F2:F6)
A9: 표시하실 때마다 자동으로 세어집니다. (엑셀에서 열면 갱신됩니다)
